# Вашей программе будет доступна функция foo, которая может бросать исключения.
#
# Вам необходимо написать код, который запускает эту функцию, затем ловит исключения ArithmeticError, AssertionError, ZeroDivisionError и выводит имя пойманного исключения.
#
# Пример решения, которое вы должны отправить на проверку.
def foo():
    pass

try:
    foo()
except ZeroDivisionError:
    print('ZeroDivisionError')
except ArithmeticError:
    print('ArithmeticError')
except AssertionError:
    print('AssertionError')